Workbook
Name WorkCentres: Config!$A$2:$A$9
Name Stations: Config!$B$2:$B$14
Name Priorities: Config!$C$2:$C$5
Name Statuses: Config!$D$2:$D$6

Sheet Config
A1: WorkCentres | B1: Stations | C1: Priorities | D1: Statuses
A2: Profiling | B2: Profiling | C2: Urgent | D2: Not Started
A3: Saw | B3: Saw | C3: High | D3: In Progress
A4: Machining | B4: Machining 1 | C4: Normal | D4: On Hold
A5: Fabrication | B5: Machining 2 | C5: Low | D5: Complete
A6: Weld | B6: Fabrication 1 | D6: Waiting Materials
A7: Blast | B7: Fabrication 2
A8: Paint | B8: Weld 1
A9: Assembly | B9: Weld 2
B10: Weld 3
B11: Blast
B12: Paint
B13: Assembly 1
B14: Assembly 2

Sheet Master Schedule
A1: PRODUCTION SCHEDULE
A2: Agricultural Machinery Manufacturer — Live Job Tracker
A4: JOB IDENTITY | M4: PROFILING | Q4: SAW | U4: MACHINING 1 | Y4: MACHINING 2 | AC4: FABRICATION 1 | AG4: FABRICATION 2 | AK4: WELD 1 | AO4: WELD 2 | AS4: WELD 3 | AW4: BLAST | BA4: PAINT | BE4: ASSEMBLY 1 | BI4: ASSEMBLY 2
A5: Job ID | B5: Customer | C5: Product/Description | D5: Order Qty | E5: Drawing Ref | F5: Job Priority | G5: Overall Status | H5: Order Due Date | I5: Date Received | J5: Days Until Due | K5: Priority Rank | L5: Notes | M5: Profiling Status | N5: Profiling Est Hrs | O5: Profiling Operator | P5: Profiling Notes | Q5: Saw Status | R5: Saw Est Hrs | S5: Saw Operator | T5: Saw Notes | U5: Machining 1 Status | V5: Machining 1 Est Hrs | W5: Machining 1 Operator | X5: Machining 1 Notes | Y5: Machining 2 Status | Z5: Machining 2 Est Hrs | AA5: Machining 2 Operator | AB5: Machining 2 Notes | AC5: Fabrication 1 Status | AD5: Fabrication 1 Est Hrs | AE5: Fabrication 1 Operator | AF5: Fabrication 1 Notes | AG5: Fabrication 2 Status | AH5: Fabrication 2 Est Hrs | AI5: Fabrication 2 Operator | AJ5: Fabrication 2 Notes | AK5: Weld 1 Status | AL5: Weld 1 Est Hrs | AM5: Weld 1 Operator | AN5: Weld 1 Notes | AO5: Weld 2 Status | AP5: Weld 2 Est Hrs | AQ5: Weld 2 Operator | AR5: Weld 2 Notes | AS5: Weld 3 Status | AT5: Weld 3 Est Hrs | AU5: Weld 3 Operator | AV5: Weld 3 Notes | AW5: Blast Status | AX5: Blast Est Hrs | AY5: Blast Operator | AZ5: Blast Notes | BA5: Paint Status | BB5: Paint Est Hrs | BC5: Paint Operator | BD5: Paint Notes | BE5: Assembly 1 Status | BF5: Assembly 1 Est Hrs | BG5: Assembly 1 Operator | BH5: Assembly 1 Notes | BI5: Assembly 2 Status | BJ5: Assembly 2 Est Hrs | BK5: Assembly 2 Operator | BL5: Assembly 2 Notes
A6: J-1001 | B6: Brennan Agri Ltd | C6: Disc Harrow 3m | D6: 5 | E6: DH-3000 | F6: Urgent | G6: In Progress | H6: 46069 | I6: 46044 | J6: =IFERROR(H6-TODAY(),"") | K6: =IFERROR(MATCH(F6,Priorities,0),99) | M6: Complete | N6: 2 | O6: Tom B. | Q6: Complete | R6: 1.5 | S6: Tom B. | U6: Complete | V6: 4 | W6: Kevin D. | Y6: Not Started | Z6: 4 | AC6: In Progress | AD6: 6 | AE6: Declan O. | AG6: Not Started | AH6: 6 | AK6: Not Started | AL6: 8 | AO6: Not Started | AP6: 8 | AS6: Not Started | AT6: 8 | AW6: Not Started | AX6: 2 | BA6: Not Started | BB6: 3 | BE6: Not Started | BF6: 5 | BI6: Not Started | BJ6: 5
A7: J-1002 | B7: Murphy Farms | C7: Muck Spreader 6T | D7: 2 | E7: MS-6000 | F7: High | G7: In Progress | H7: 46072 | I7: 46049 | J7: =IFERROR(H7-TODAY(),"") | K7: =IFERROR(MATCH(F7,Priorities,0),99) | M7: Complete | N7: 2 | O7: Tom B. | Q7: Complete | R7: 1.5 | S7: Tom B. | U7: Not Started | V7: 4 | Y7: Not Started | Z7: 4 | AC7: Complete | AD7: 6 | AE7: Declan O. | AG7: In Progress | AH7: 6 | AI7: Declan O. | AK7: Not Started | AL7: 8 | AO7: Not Started | AP7: 8 | AS7: Not Started | AT7: 8 | AW7: Not Started | AX7: 2 | BA7: Not Started | BB7: 3 | BE7: Not Started | BF7: 5 | BI7: Not Started | BJ7: 5
A8: J-1003 | B8: O'Brien Tillage | C8: Subsoiler 5-Leg | D8: 3 | E8: SS-0500 | F8: Urgent | G8: In Progress | H8: 46066 | I8: 46034 | J8: =IFERROR(H8-TODAY(),"") | K8: =IFERROR(MATCH(F8,Priorities,0),99) | M8: Complete | N8: 2 | O8: Sean R. | Q8: Complete | R8: 1.5 | S8: Tom B. | U8: Complete | V8: 4 | W8: Pat M. | Y8: Complete | Z8: 4 | AA8: Pat M. | AC8: Complete | AD8: 6 | AE8: Declan O. | AG8: Not Started | AH8: 6 | AK8: In Progress | AL8: 8 | AM8: Ciaran W. | AO8: Not Started | AP8: 8 | AS8: Not Started | AT8: 8 | AW8: Not Started | AX8: 2 | BA8: Not Started | BB8: 3 | BE8: Not Started | BF8: 5 | BI8: Not Started | BJ8: 5
A9: J-1004 | B9: Kelly Contracting | C9: Bale Handler Twin | D9: 4 | E9: BH-2000 | F9: High | G9: In Progress | H9: 46076 | I9: 46054 | J9: =IFERROR(H9-TODAY(),"") | K9: =IFERROR(MATCH(F9,Priorities,0),99) | M9: Complete | N9: 2 | O9: Tom B. | Q9: Complete | R9: 1.5 | S9: Tom B. | U9: Not Started | V9: 4 | Y9: Not Started | Z9: 4 | AC9: Complete | AD9: 6 | AE9: Brian S. | AG9: Not Started | AH9: 6 | AK9: Complete | AL9: 8 | AM9: Ciaran W. | AO9: In Progress | AP9: 8 | AQ9: Dave L. | AS9: Not Started | AT9: 8 | AW9: Not Started | AX9: 2 | BA9: Not Started | BB9: 3 | BE9: Not Started | BF9: 5 | BI9: Not Started | BJ9: 5
A10: J-1005 | B10: Walsh Plant Hire | C10: Roller Cambridge 4m | D10: 1 | E10: RC-4000 | F10: Normal | G10: In Progress | H10: 46081 | I10: 46059 | J10: =IFERROR(H10-TODAY(),"") | K10: =IFERROR(MATCH(F10,Priorities,0),99) | M10: Complete | N10: 2 | O10: Sean R. | Q10: Complete | R10: 1.5 | S10: Tom B. | U10: Not Started | V10: 4 | Y10: Not Started | Z10: 4 | AC10: In Progress | AD10: 6 | AE10: Declan O. | AG10: Not Started | AH10: 6 | AK10: Not Started | AL10: 8 | AO10: Not Started | AP10: 8 | AS10: Not Started | AT10: 8 | AW10: Not Started | AX10: 2 | BA10: Not Started | BB10: 3 | BE10: Not Started | BF10: 5 | BI10: Not Started | BJ10: 5
A11: J-1006 | B11: Fitzpatrick Agri | C11: Trailer 14T Grain | D11: 2 | E11: TG-1400 | F11: Normal | G11: Not Started | H11: 46088 | I11: 46064 | J11: =IFERROR(H11-TODAY(),"") | K11: =IFERROR(MATCH(F11,Priorities,0),99) | M11: Not Started | N11: 2 | Q11: Not Started | R11: 1.5 | U11: Not Started | V11: 4 | Y11: Not Started | Z11: 4 | AC11: Not Started | AD11: 6 | AG11: Not Started | AH11: 6 | AK11: Not Started | AL11: 8 | AO11: Not Started | AP11: 8 | AS11: Not Started | AT11: 8 | AW11: Not Started | AX11: 2 | BA11: Not Started | BB11: 3 | BE11: Not Started | BF11: 5 | BI11: Not Started | BJ11: 5
A12: J-1007 | B12: Connolly & Sons | C12: Disc Harrow 4m | D12: 3 | E12: DH-4000 | F12: High | G12: In Progress | H12: 46075 | I12: 46056 | J12: =IFERROR(H12-TODAY(),"") | K12: =IFERROR(MATCH(F12,Priorities,0),99) | M12: Complete | N12: 2 | O12: Sean R. | Q12: Complete | R12: 1.5 | S12: Liam F. | U12: In Progress | V12: 4 | W12: Kevin D. | Y12: Not Started | Z12: 4 | AC12: Not Started | AD12: 6 | AG12: Not Started | AH12: 6 | AK12: Not Started | AL12: 8 | AO12: Not Started | AP12: 8 | AS12: Not Started | AT12: 8 | AW12: Not Started | AX12: 2 | BA12: Not Started | BB12: 3 | BE12: Not Started | BF12: 5 | BI12: Not Started | BJ12: 5
A13: J-1008 | B13: Riordan Farm Supplies | C13: Muck Spreader 8T | D13: 1 | E13: MS-8000 | F13: Low | G13: Not Started | H13: 46095 | I13: 46069 | J13: =IFERROR(H13-TODAY(),"") | K13: =IFERROR(MATCH(F13,Priorities,0),99) | M13: Not Started | N13: 2 | Q13: Not Started | R13: 1.5 | U13: Not Started | V13: 4 | Y13: Not Started | Z13: 4 | AC13: Not Started | AD13: 6 | AG13: Not Started | AH13: 6 | AK13: Not Started | AL13: 8 | AO13: Not Started | AP13: 8 | AS13: Not Started | AT13: 8 | AW13: Not Started | AX13: 2 | BA13: Not Started | BB13: 3 | BE13: Not Started | BF13: 5 | BI13: Not Started | BJ13: 5
A14: J-1009 | B14: Daly Agri Repairs | C14: Subsoiler 7-Leg | D14: 2 | E14: SS-0700 | F14: Normal | G14: In Progress | H14: 46077 | I14: 46052 | J14: =IFERROR(H14-TODAY(),"") | K14: =IFERROR(MATCH(F14,Priorities,0),99) | M14: Complete | N14: 2 | O14: Tom B. | Q14: In Progress | R14: 1.5 | S14: Tom B. | U14: Not Started | V14: 4 | Y14: Not Started | Z14: 4 | AC14: Not Started | AD14: 6 | AG14: Not Started | AH14: 6 | AK14: Not Started | AL14: 8 | AO14: Not Started | AP14: 8 | AS14: Not Started | AT14: 8 | AW14: Not Started | AX14: 2 | BA14: Not Started | BB14: 3 | BE14: Not Started | BF14: 5 | BI14: Not Started | BJ14: 5
A15: J-1010 | B15: Burke Plant | C15: Bale Handler Single | D15: 6 | E15: BH-1000 | F15: Urgent | G15: In Progress | H15: 46071 | I15: 46039 | J15: =IFERROR(H15-TODAY(),"") | K15: =IFERROR(MATCH(F15,Priorities,0),99) | M15: Complete | N15: 2 | O15: Sean R. | Q15: Complete | R15: 1.5 | S15: Tom B. | U15: Not Started | V15: 4 | Y15: Not Started | Z15: 4 | AC15: Complete | AD15: 6 | AE15: Declan O. | AG15: Not Started | AH15: 6 | AK15: Complete | AL15: 8 | AM15: Eoin P. | AO15: Complete | AP15: 8 | AQ15: Ciaran W. | AS15: Not Started | AT15: 8 | AW15: In Progress | AX15: 2 | AY15: Alan F. | BA15: Not Started | BB15: 3 | BE15: Not Started | BF15: 5 | BI15: Not Started | BJ15: 5
A16: J-1011 | B16: Healy Farms | C16: Roller Flat 3m | D16: 2 | E16: RF-3000 | F16: Normal | G16: Not Started | H16: 46084 | I16: 46062 | J16: =IFERROR(H16-TODAY(),"") | K16: =IFERROR(MATCH(F16,Priorities,0),99) | M16: Not Started | N16: 2 | Q16: Not Started | R16: 1.5 | U16: Not Started | V16: 4 | Y16: Not Started | Z16: 4 | AC16: Not Started | AD16: 6 | AG16: Not Started | AH16: 6 | AK16: Not Started | AL16: 8 | AO16: Not Started | AP16: 8 | AS16: Not Started | AT16: 8 | AW16: Not Started | AX16: 2 | BA16: Not Started | BB16: 3 | BE16: Not Started | BF16: 5 | BI16: Not Started | BJ16: 5
A17: J-1012 | B17: Sheehan Contracting | C17: Trailer 10T Grain | D17: 3 | E17: TG-1000 | F17: High | G17: In Progress | H17: 46074 | I17: 46046 | J17: =IFERROR(H17-TODAY(),"") | K17: =IFERROR(MATCH(F17,Priorities,0),99) | M17: Complete | N17: 2 | O17: Sean R. | Q17: Complete | R17: 1.5 | S17: Liam F. | U17: Not Started | V17: 4 | Y17: Not Started | Z17: 4 | AC17: Complete | AD17: 6 | AE17: Declan O. | AG17: Complete | AH17: 6 | AI17: Mark T. | AK17: Complete | AL17: 8 | AM17: Ciaran W. | AO17: In Progress | AP17: 8 | AQ17: Dave L. | AS17: Not Started | AT17: 8 | AW17: Not Started | AX17: 2 | BA17: Not Started | BB17: 3 | BE17: Not Started | BF17: 5 | BI17: Not Started | BJ17: 5
A18: J-1013 | B18: O'Sullivan Plant Hire | C18: Disc Harrow 5m | D18: 2 | E18: DH-5000 | F18: Low | G18: Not Started | H18: 46104 | I18: 46071 | J18: =IFERROR(H18-TODAY(),"") | K18: =IFERROR(MATCH(F18,Priorities,0),99) | M18: Not Started | N18: 2 | Q18: Not Started | R18: 1.5 | U18: Not Started | V18: 4 | Y18: Not Started | Z18: 4 | AC18: Not Started | AD18: 6 | AG18: Not Started | AH18: 6 | AK18: Not Started | AL18: 8 | AO18: Not Started | AP18: 8 | AS18: Not Started | AT18: 8 | AW18: Not Started | AX18: 2 | BA18: Not Started | BB18: 3 | BE18: Not Started | BF18: 5 | BI18: Not Started | BJ18: 5
A19: J-1014 | B19: Cronin Agri | C19: Muck Spreader 10T | D19: 1 | E19: MS-A000 | F19: High | G19: Waiting Materials | H19: 46076 | I19: 46054 | J19: =IFERROR(H19-TODAY(),"") | K19: =IFERROR(MATCH(F19,Priorities,0),99) | M19: Waiting Materials | N19: 2 | O19: Tom B. | Q19: Not Started | R19: 1.5 | U19: Not Started | V19: 4 | Y19: Not Started | Z19: 4 | AC19: Not Started | AD19: 6 | AG19: Not Started | AH19: 6 | AK19: Not Started | AL19: 8 | AO19: Not Started | AP19: 8 | AS19: Not Started | AT19: 8 | AW19: Not Started | AX19: 2 | BA19: Not Started | BB19: 3 | BE19: Not Started | BF19: 5 | BI19: Not Started | BJ19: 5
A20: J-1015 | B20: McCarthy Farm Equip | C20: Subsoiler 3-Leg | D20: 4 | E20: SS-0300 | F20: Normal | G20: Not Started | H20: 46092 | I20: 46066 | J20: =IFERROR(H20-TODAY(),"") | K20: =IFERROR(MATCH(F20,Priorities,0),99) | M20: Not Started | N20: 2 | Q20: Not Started | R20: 1.5 | U20: Not Started | V20: 4 | Y20: Not Started | Z20: 4 | AC20: Not Started | AD20: 6 | AG20: Not Started | AH20: 6 | AK20: Not Started | AL20: 8 | AO20: Not Started | AP20: 8 | AS20: Not Started | AT20: 8 | AW20: Not Started | AX20: 2 | BA20: Not Started | BB20: 3 | BE20: Not Started | BF20: 5 | BI20: Not Started | BJ20: 5
A21: J-1016 | B21: Power Agri Ltd | C21: Bale Handler Triple | D21: 2 | E21: BH-3000 | F21: Urgent | G21: In Progress | H21: 46073 | I21: 46029 | J21: =IFERROR(H21-TODAY(),"") | K21: =IFERROR(MATCH(F21,Priorities,0),99) | M21: Complete | N21: 2 | O21: Sean R. | Q21: Complete | R21: 1.5 | S21: Liam F. | U21: Complete | V21: 4 | W21: Pat M. | Y21: Complete | Z21: 4 | AA21: Pat M. | AC21: Complete | AD21: 6 | AE21: Declan O. | AG21: Complete | AH21: 6 | AI21: Declan O. | AK21: Complete | AL21: 8 | AM21: Eoin P. | AO21: Complete | AP21: 8 | AQ21: Ciaran W. | AS21: Complete | AT21: 8 | AU21: Shane C. | AW21: Complete | AX21: 2 | AY21: Paul G. | BA21: In Progress | BB21: 3 | BC21: Ger M. | BE21: Not Started | BF21: 5 | BI21: Not Started | BJ21: 5
A22: J-1017 | B22: Nolan Plant | C22: Roller Cambridge 6m | D22: 1 | E22: RC-6000 | F22: Normal | G22: Not Started | H22: 46099 | I22: 46068 | J22: =IFERROR(H22-TODAY(),"") | K22: =IFERROR(MATCH(F22,Priorities,0),99) | M22: Not Started | N22: 2 | Q22: Not Started | R22: 1.5 | U22: Not Started | V22: 4 | Y22: Not Started | Z22: 4 | AC22: Not Started | AD22: 6 | AG22: Not Started | AH22: 6 | AK22: Not Started | AL22: 8 | AO22: Not Started | AP22: 8 | AS22: Not Started | AT22: 8 | AW22: Not Started | AX22: 2 | BA22: Not Started | BB22: 3 | BE22: Not Started | BF22: 5 | BI22: Not Started | BJ22: 5
A23: J-1018 | B23: Treacy Agri Supplies | C23: Trailer 16T Grain | D23: 2 | E23: TG-1600 | F23: High | G23: On Hold | H23: 46077 | I23: 46042 | J23: =IFERROR(H23-TODAY(),"") | K23: =IFERROR(MATCH(F23,Priorities,0),99) | M23: Complete | N23: 2 | O23: Sean R. | Q23: Complete | R23: 1.5 | S23: Liam F. | U23: Not Started | V23: 4 | Y23: Not Started | Z23: 4 | AC23: On Hold | AD23: 6 | AE23: Brian S. | AG23: Not Started | AH23: 6 | AK23: Not Started | AL23: 8 | AO23: Not Started | AP23: 8 | AS23: Not Started | AT23: 8 | AW23: Not Started | AX23: 2 | BA23: Not Started | BB23: 3 | BE23: Not Started | BF23: 5 | BI23: Not Started | BJ23: 5
A24: J-1019 | B24: Delaney Farms | C24: Disc Harrow 6m | D24: 1 | E24: DH-6000 | F24: Low | G24: Not Started | H24: 46119 | I24: 46072 | J24: =IFERROR(H24-TODAY(),"") | K24: =IFERROR(MATCH(F24,Priorities,0),99) | M24: Not Started | N24: 2 | Q24: Not Started | R24: 1.5 | U24: Not Started | V24: 4 | Y24: Not Started | Z24: 4 | AC24: Not Started | AD24: 6 | AG24: Not Started | AH24: 6 | AK24: Not Started | AL24: 8 | AO24: Not Started | AP24: 8 | AS24: Not Started | AT24: 8 | AW24: Not Started | AX24: 2 | BA24: Not Started | BB24: 3 | BE24: Not Started | BF24: 5 | BI24: Not Started | BJ24: 5
A25: J-1020 | B25: Flynn Contracting | C25: Muck Spreader 4T | D25: 3 | E25: MS-4000 | F25: Normal | G25: In Progress | H25: 46080 | I25: 46060 | J25: =IFERROR(H25-TODAY(),"") | K25: =IFERROR(MATCH(F25,Priorities,0),99) | M25: Complete | N25: 2 | O25: Tom B. | Q25: In Progress | R25: 1.5 | S25: Liam F. | U25: Not Started | V25: 4 | Y25: Not Started | Z25: 4 | AC25: Not Started | AD25: 6 | AG25: Not Started | AH25: 6 | AK25: Not Started | AL25: 8 | AO25: Not Started | AP25: 8 | AS25: Not Started | AT25: 8 | AW25: Not Started | AX25: 2 | BA25: Not Started | BB25: 3 | BE25: Not Started | BF25: 5 | BI25: Not Started | BJ25: 5
A26: J-1021 | B26: Higgins Farm Mach. | C26: Subsoiler 9-Leg | D26: 1 | E26: SS-0900 | F26: High | G26: In Progress | H26: 46075 | I26: 46048 | J26: =IFERROR(H26-TODAY(),"") | K26: =IFERROR(MATCH(F26,Priorities,0),99) | M26: Complete | N26: 2 | O26: Sean R. | Q26: Complete | R26: 1.5 | S26: Tom B. | U26: Complete | V26: 4 | W26: Kevin D. | Y26: Not Started | Z26: 4 | AC26: In Progress | AD26: 6 | AE26: Declan O. | AG26: Not Started | AH26: 6 | AK26: Not Started | AL26: 8 | AO26: Not Started | AP26: 8 | AS26: Not Started | AT26: 8 | AW26: Not Started | AX26: 2 | BA26: Not Started | BB26: 3 | BE26: Not Started | BF26: 5 | BI26: Not Started | BJ26: 5
A27: J-1022 | B27: Egan Plant Hire | C27: Bale Handler Twin XL | D27: 2 | E27: BH-2100 | F27: Normal | G27: Not Started | H27: 46086 | I27: 46065 | J27: =IFERROR(H27-TODAY(),"") | K27: =IFERROR(MATCH(F27,Priorities,0),99) | M27: Not Started | N27: 2 | Q27: Not Started | R27: 1.5 | U27: Not Started | V27: 4 | Y27: Not Started | Z27: 4 | AC27: Not Started | AD27: 6 | AG27: Not Started | AH27: 6 | AK27: Not Started | AL27: 8 | AO27: Not Started | AP27: 8 | AS27: Not Started | AT27: 8 | AW27: Not Started | AX27: 2 | BA27: Not Started | BB27: 3 | BE27: Not Started | BF27: 5 | BI27: Not Started | BJ27: 5
A28: J-1023 | B28: Ryan Agri | C28: Roller Flat 5m | D28: 2 | E28: RF-5000 | F28: Urgent | G28: Complete | H28: 46068 | I28: 46024 | J28: =IFERROR(H28-TODAY(),"") | K28: =IFERROR(MATCH(F28,Priorities,0),99) | M28: Complete | N28: 2 | O28: Tom B. | Q28: Complete | R28: 1.5 | S28: Tom B. | U28: Not Started | V28: 4 | Y28: Not Started | Z28: 4 | AC28: Complete | AD28: 6 | AE28: Declan O. | AG28: Complete | AH28: 6 | AI28: Mark T. | AK28: Complete | AL28: 8 | AM28: Eoin P. | AO28: Complete | AP28: 8 | AQ28: Dave L. | AS28: Complete | AT28: 8 | AU28: Shane C. | AW28: Complete | AX28: 2 | AY28: Alan F. | BA28: Complete | BB28: 3 | BC28: Paul G. | BE28: Complete | BF28: 5 | BG28: Frank D. | BI28: Complete | BJ28: 5 | BK28: Frank D.
A29: J-1024 | B29: Dooley Farm Supplies | C29: Trailer 8T Silage | D29: 3 | E29: TS-0800 | F29: Low | G29: Not Started | H29: 46109 | I29: 46070 | J29: =IFERROR(H29-TODAY(),"") | K29: =IFERROR(MATCH(F29,Priorities,0),99) | M29: Not Started | N29: 2 | Q29: Not Started | R29: 1.5 | U29: Not Started | V29: 4 | Y29: Not Started | Z29: 4 | AC29: Not Started | AD29: 6 | AG29: Not Started | AH29: 6 | AK29: Not Started | AL29: 8 | AO29: Not Started | AP29: 8 | AS29: Not Started | AT29: 8 | AW29: Not Started | AX29: 2 | BA29: Not Started | BB29: 3 | BE29: Not Started | BF29: 5 | BI29: Not Started | BJ29: 5
A30: J-1025 | B30: Kavanagh Agri Ltd | C30: Disc Harrow 2.5m Folding | D30: 4 | E30: DH-2500 | F30: High | G30: Waiting Materials | H30: 46076 | I30: 46057 | J30: =IFERROR(H30-TODAY(),"") | K30: =IFERROR(MATCH(F30,Priorities,0),99) | M30: Complete | N30: 2 | O30: Sean R. | Q30: Complete | R30: 1.5 | S30: Liam F. | U30: Waiting Materials | V30: 4 | W30: Kevin D. | Y30: Not Started | Z30: 4 | AC30: Not Started | AD30: 6 | AG30: Not Started | AH30: 6 | AK30: Not Started | AL30: 8 | AO30: Not Started | AP30: 8 | AS30: Not Started | AT30: 8 | AW30: Not Started | AX30: 2 | BA30: Not Started | BB30: 3 | BE30: Not Started | BF30: 5 | BI30: Not Started | BJ30: 5

Sheet Dashboard
A1: PRODUCTION DASHBOARD
A2: Manager Overview — Live KPIs
A4: Total Active Jobs | D4: Overdue Jobs | G4: Due This Week | J4: Total Remaining Est Hrs
A5: =COUNTIF('Master Schedule'!$G$6:$G$500,"<>Complete") | D5: =SUMPRODUCT(('Master Schedule'!$J$6:$J$500<0)*('Master Schedule'!$G$6:$G$500<>"Complete")*('Master Schedule'!$A$6:$A$500<>"")) | G5: =SUMPRODUCT(('Master Schedule'!$J$6:$J$500>=0)*('Master Schedule'!$J$6:$J$500<=7)*('Master Schedule'!$G$6:$G$500<>"Complete")*('Master Schedule'!$A$6:$A$500<>"")) | J5: =SUMPRODUCT(('Master Schedule'!$G$6:$G$500<>"Complete")*('Master Schedule'!$A$6:$A$500<>"")*(('Master Schedule'!$N$6:$N$500)+('Master Schedule'!$R$6:$R$500)+('Master Schedule'!$V$6:$V$500)+('Master Schedule'!$Z$6:$Z$500)+('Master Schedule'!$AD$6:$AD$500)+('Master Schedule'!$AH$6:$AH$500)+('Master Schedule'!$AL$6:$AL$500)+('Master Schedule'!$AP$6:$AP$500)+('Master Schedule'!$AT$6:$AT$500)+('Master Schedule'!$AX$6:$AX$500)+('Master Schedule'!$BB$6:$BB$500)+('Master Schedule'!$BF$6:$BF$500)+('Master Schedule'!$BJ$6:$BJ$500)))
A8: Station | B8: Jobs Queued | C8: Remaining Hrs | D8: Urgent | E8: High | F8: Normal | G8: Low | H8: Overdue | I8: Due This Week | J8: % Complete
A9: Profiling | B9: =SUMPRODUCT(('Master Schedule'!$M$6:$M$500<>"Complete")*('Master Schedule'!$M$6:$M$500<>"Not Started")*('Master Schedule'!$A$6:$A$500<>"")) | C9: =SUMPRODUCT(('Master Schedule'!$M$6:$M$500<>"Complete")*('Master Schedule'!$A$6:$A$500<>"")*'Master Schedule'!$N$6:$N$500) | D9: =SUMPRODUCT(('Master Schedule'!$M$6:$M$500<>"Complete")*('Master Schedule'!$M$6:$M$500<>"Not Started")*('Master Schedule'!$F$6:$F$500="Urgent")*('Master Schedule'!$A$6:$A$500<>"")) | E9: =SUMPRODUCT(('Master Schedule'!$M$6:$M$500<>"Complete")*('Master Schedule'!$M$6:$M$500<>"Not Started")*('Master Schedule'!$F$6:$F$500="High")*('Master Schedule'!$A$6:$A$500<>"")) | F9: =SUMPRODUCT(('Master Schedule'!$M$6:$M$500<>"Complete")*('Master Schedule'!$M$6:$M$500<>"Not Started")*('Master Schedule'!$F$6:$F$500="Normal")*('Master Schedule'!$A$6:$A$500<>"")) | G9: =SUMPRODUCT(('Master Schedule'!$M$6:$M$500<>"Complete")*('Master Schedule'!$M$6:$M$500<>"Not Started")*('Master Schedule'!$F$6:$F$500="Low")*('Master Schedule'!$A$6:$A$500<>"")) | H9: =SUMPRODUCT(('Master Schedule'!$M$6:$M$500<>"Complete")*('Master Schedule'!$M$6:$M$500<>"Not Started")*('Master Schedule'!$J$6:$J$500<0)*('Master Schedule'!$A$6:$A$500<>"")) | I9: =SUMPRODUCT(('Master Schedule'!$M$6:$M$500<>"Complete")*('Master Schedule'!$M$6:$M$500<>"Not Started")*('Master Schedule'!$J$6:$J$500>=0)*('Master Schedule'!$J$6:$J$500<=7)*('Master Schedule'!$A$6:$A$500<>"")) | J9: =IFERROR(SUMPRODUCT(('Master Schedule'!$M$6:$M$500="Complete")*('Master Schedule'!$A$6:$A$500<>""))/SUMPRODUCT(('Master Schedule'!$A$6:$A$500<>"")*1),0)
A10: Saw | B10: =SUMPRODUCT(('Master Schedule'!$Q$6:$Q$500<>"Complete")*('Master Schedule'!$Q$6:$Q$500<>"Not Started")*('Master Schedule'!$A$6:$A$500<>"")) | C10: =SUMPRODUCT(('Master Schedule'!$Q$6:$Q$500<>"Complete")*('Master Schedule'!$A$6:$A$500<>"")*'Master Schedule'!$R$6:$R$500) | D10: =SUMPRODUCT(('Master Schedule'!$Q$6:$Q$500<>"Complete")*('Master Schedule'!$Q$6:$Q$500<>"Not Started")*('Master Schedule'!$F$6:$F$500="Urgent")*('Master Schedule'!$A$6:$A$500<>"")) | E10: =SUMPRODUCT(('Master Schedule'!$Q$6:$Q$500<>"Complete")*('Master Schedule'!$Q$6:$Q$500<>"Not Started")*('Master Schedule'!$F$6:$F$500="High")*('Master Schedule'!$A$6:$A$500<>"")) | F10: =SUMPRODUCT(('Master Schedule'!$Q$6:$Q$500<>"Complete")*('Master Schedule'!$Q$6:$Q$500<>"Not Started")*('Master Schedule'!$F$6:$F$500="Normal")*('Master Schedule'!$A$6:$A$500<>"")) | G10: =SUMPRODUCT(('Master Schedule'!$Q$6:$Q$500<>"Complete")*('Master Schedule'!$Q$6:$Q$500<>"Not Started")*('Master Schedule'!$F$6:$F$500="Low")*('Master Schedule'!$A$6:$A$500<>"")) | H10: =SUMPRODUCT(('Master Schedule'!$Q$6:$Q$500<>"Complete")*('Master Schedule'!$Q$6:$Q$500<>"Not Started")*('Master Schedule'!$J$6:$J$500<0)*('Master Schedule'!$A$6:$A$500<>"")) | I10: =SUMPRODUCT(('Master Schedule'!$Q$6:$Q$500<>"Complete")*('Master Schedule'!$Q$6:$Q$500<>"Not Started")*('Master Schedule'!$J$6:$J$500>=0)*('Master Schedule'!$J$6:$J$500<=7)*('Master Schedule'!$A$6:$A$500<>"")) | J10: =IFERROR(SUMPRODUCT(('Master Schedule'!$Q$6:$Q$500="Complete")*('Master Schedule'!$A$6:$A$500<>""))/SUMPRODUCT(('Master Schedule'!$A$6:$A$500<>"")*1),0)
A11: Machining 1 | B11: =SUMPRODUCT(('Master Schedule'!$U$6:$U$500<>"Complete")*('Master Schedule'!$U$6:$U$500<>"Not Started")*('Master Schedule'!$A$6:$A$500<>"")) | C11: =SUMPRODUCT(('Master Schedule'!$U$6:$U$500<>"Complete")*('Master Schedule'!$A$6:$A$500<>"")*'Master Schedule'!$V$6:$V$500) | D11: =SUMPRODUCT(('Master Schedule'!$U$6:$U$500<>"Complete")*('Master Schedule'!$U$6:$U$500<>"Not Started")*('Master Schedule'!$F$6:$F$500="Urgent")*('Master Schedule'!$A$6:$A$500<>"")) | E11: =SUMPRODUCT(('Master Schedule'!$U$6:$U$500<>"Complete")*('Master Schedule'!$U$6:$U$500<>"Not Started")*('Master Schedule'!$F$6:$F$500="High")*('Master Schedule'!$A$6:$A$500<>"")) | F11: =SUMPRODUCT(('Master Schedule'!$U$6:$U$500<>"Complete")*('Master Schedule'!$U$6:$U$500<>"Not Started")*('Master Schedule'!$F$6:$F$500="Normal")*('Master Schedule'!$A$6:$A$500<>"")) | G11: =SUMPRODUCT(('Master Schedule'!$U$6:$U$500<>"Complete")*('Master Schedule'!$U$6:$U$500<>"Not Started")*('Master Schedule'!$F$6:$F$500="Low")*('Master Schedule'!$A$6:$A$500<>"")) | H11: =SUMPRODUCT(('Master Schedule'!$U$6:$U$500<>"Complete")*('Master Schedule'!$U$6:$U$500<>"Not Started")*('Master Schedule'!$J$6:$J$500<0)*('Master Schedule'!$A$6:$A$500<>"")) | I11: =SUMPRODUCT(('Master Schedule'!$U$6:$U$500<>"Complete")*('Master Schedule'!$U$6:$U$500<>"Not Started")*('Master Schedule'!$J$6:$J$500>=0)*('Master Schedule'!$J$6:$J$500<=7)*('Master Schedule'!$A$6:$A$500<>"")) | J11: =IFERROR(SUMPRODUCT(('Master Schedule'!$U$6:$U$500="Complete")*('Master Schedule'!$A$6:$A$500<>""))/SUMPRODUCT(('Master Schedule'!$A$6:$A$500<>"")*1),0)
A12: Machining 2 | B12: =SUMPRODUCT(('Master Schedule'!$Y$6:$Y$500<>"Complete")*('Master Schedule'!$Y$6:$Y$500<>"Not Started")*('Master Schedule'!$A$6:$A$500<>"")) | C12: =SUMPRODUCT(('Master Schedule'!$Y$6:$Y$500<>"Complete")*('Master Schedule'!$A$6:$A$500<>"")*'Master Schedule'!$Z$6:$Z$500) | D12: =SUMPRODUCT(('Master Schedule'!$Y$6:$Y$500<>"Complete")*('Master Schedule'!$Y$6:$Y$500<>"Not Started")*('Master Schedule'!$F$6:$F$500="Urgent")*('Master Schedule'!$A$6:$A$500<>"")) | E12: =SUMPRODUCT(('Master Schedule'!$Y$6:$Y$500<>"Complete")*('Master Schedule'!$Y$6:$Y$500<>"Not Started")*('Master Schedule'!$F$6:$F$500="High")*('Master Schedule'!$A$6:$A$500<>"")) | F12: =SUMPRODUCT(('Master Schedule'!$Y$6:$Y$500<>"Complete")*('Master Schedule'!$Y$6:$Y$500<>"Not Started")*('Master Schedule'!$F$6:$F$500="Normal")*('Master Schedule'!$A$6:$A$500<>"")) | G12: =SUMPRODUCT(('Master Schedule'!$Y$6:$Y$500<>"Complete")*('Master Schedule'!$Y$6:$Y$500<>"Not Started")*('Master Schedule'!$F$6:$F$500="Low")*('Master Schedule'!$A$6:$A$500<>"")) | H12: =SUMPRODUCT(('Master Schedule'!$Y$6:$Y$500<>"Complete")*('Master Schedule'!$Y$6:$Y$500<>"Not Started")*('Master Schedule'!$J$6:$J$500<0)*('Master Schedule'!$A$6:$A$500<>"")) | I12: =SUMPRODUCT(('Master Schedule'!$Y$6:$Y$500<>"Complete")*('Master Schedule'!$Y$6:$Y$500<>"Not Started")*('Master Schedule'!$J$6:$J$500>=0)*('Master Schedule'!$J$6:$J$500<=7)*('Master Schedule'!$A$6:$A$500<>"")) | J12: =IFERROR(SUMPRODUCT(('Master Schedule'!$Y$6:$Y$500="Complete")*('Master Schedule'!$A$6:$A$500<>""))/SUMPRODUCT(('Master Schedule'!$A$6:$A$500<>"")*1),0)
A13: Fabrication 1 | B13: =SUMPRODUCT(('Master Schedule'!$AC$6:$AC$500<>"Complete")*('Master Schedule'!$AC$6:$AC$500<>"Not Started")*('Master Schedule'!$A$6:$A$500<>"")) | C13: =SUMPRODUCT(('Master Schedule'!$AC$6:$AC$500<>"Complete")*('Master Schedule'!$A$6:$A$500<>"")*'Master Schedule'!$AD$6:$AD$500) | D13: =SUMPRODUCT(('Master Schedule'!$AC$6:$AC$500<>"Complete")*('Master Schedule'!$AC$6:$AC$500<>"Not Started")*('Master Schedule'!$F$6:$F$500="Urgent")*('Master Schedule'!$A$6:$A$500<>"")) | E13: =SUMPRODUCT(('Master Schedule'!$AC$6:$AC$500<>"Complete")*('Master Schedule'!$AC$6:$AC$500<>"Not Started")*('Master Schedule'!$F$6:$F$500="High")*('Master Schedule'!$A$6:$A$500<>"")) | F13: =SUMPRODUCT(('Master Schedule'!$AC$6:$AC$500<>"Complete")*('Master Schedule'!$AC$6:$AC$500<>"Not Started")*('Master Schedule'!$F$6:$F$500="Normal")*('Master Schedule'!$A$6:$A$500<>"")) | G13: =SUMPRODUCT(('Master Schedule'!$AC$6:$AC$500<>"Complete")*('Master Schedule'!$AC$6:$AC$500<>"Not Started")*('Master Schedule'!$F$6:$F$500="Low")*('Master Schedule'!$A$6:$A$500<>"")) | H13: =SUMPRODUCT(('Master Schedule'!$AC$6:$AC$500<>"Complete")*('Master Schedule'!$AC$6:$AC$500<>"Not Started")*('Master Schedule'!$J$6:$J$500<0)*('Master Schedule'!$A$6:$A$500<>"")) | I13: =SUMPRODUCT(('Master Schedule'!$AC$6:$AC$500<>"Complete")*('Master Schedule'!$AC$6:$AC$500<>"Not Started")*('Master Schedule'!$J$6:$J$500>=0)*('Master Schedule'!$J$6:$J$500<=7)*('Master Schedule'!$A$6:$A$500<>"")) | J13: =IFERROR(SUMPRODUCT(('Master Schedule'!$AC$6:$AC$500="Complete")*('Master Schedule'!$A$6:$A$500<>""))/SUMPRODUCT(('Master Schedule'!$A$6:$A$500<>"")*1),0)
A14: Fabrication 2 | B14: =SUMPRODUCT(('Master Schedule'!$AG$6:$AG$500<>"Complete")*('Master Schedule'!$AG$6:$AG$500<>"Not Started")*('Master Schedule'!$A$6:$A$500<>"")) | C14: =SUMPRODUCT(('Master Schedule'!$AG$6:$AG$500<>"Complete")*('Master Schedule'!$A$6:$A$500<>"")*'Master Schedule'!$AH$6:$AH$500) | D14: =SUMPRODUCT(('Master Schedule'!$AG$6:$AG$500<>"Complete")*('Master Schedule'!$AG$6:$AG$500<>"Not Started")*('Master Schedule'!$F$6:$F$500="Urgent")*('Master Schedule'!$A$6:$A$500<>"")) | E14: =SUMPRODUCT(('Master Schedule'!$AG$6:$AG$500<>"Complete")*('Master Schedule'!$AG$6:$AG$500<>"Not Started")*('Master Schedule'!$F$6:$F$500="High")*('Master Schedule'!$A$6:$A$500<>"")) | F14: =SUMPRODUCT(('Master Schedule'!$AG$6:$AG$500<>"Complete")*('Master Schedule'!$AG$6:$AG$500<>"Not Started")*('Master Schedule'!$F$6:$F$500="Normal")*('Master Schedule'!$A$6:$A$500<>"")) | G14: =SUMPRODUCT(('Master Schedule'!$AG$6:$AG$500<>"Complete")*('Master Schedule'!$AG$6:$AG$500<>"Not Started")*('Master Schedule'!$F$6:$F$500="Low")*('Master Schedule'!$A$6:$A$500<>"")) | H14: =SUMPRODUCT(('Master Schedule'!$AG$6:$AG$500<>"Complete")*('Master Schedule'!$AG$6:$AG$500<>"Not Started")*('Master Schedule'!$J$6:$J$500<0)*('Master Schedule'!$A$6:$A$500<>"")) | I14: =SUMPRODUCT(('Master Schedule'!$AG$6:$AG$500<>"Complete")*('Master Schedule'!$AG$6:$AG$500<>"Not Started")*('Master Schedule'!$J$6:$J$500>=0)*('Master Schedule'!$J$6:$J$500<=7)*('Master Schedule'!$A$6:$A$500<>"")) | J14: =IFERROR(SUMPRODUCT(('Master Schedule'!$AG$6:$AG$500="Complete")*('Master Schedule'!$A$6:$A$500<>""))/SUMPRODUCT(('Master Schedule'!$A$6:$A$500<>"")*1),0)
A15: Weld 1 | B15: =SUMPRODUCT(('Master Schedule'!$AK$6:$AK$500<>"Complete")*('Master Schedule'!$AK$6:$AK$500<>"Not Started")*('Master Schedule'!$A$6:$A$500<>"")) | C15: =SUMPRODUCT(('Master Schedule'!$AK$6:$AK$500<>"Complete")*('Master Schedule'!$A$6:$A$500<>"")*'Master Schedule'!$AL$6:$AL$500) | D15: =SUMPRODUCT(('Master Schedule'!$AK$6:$AK$500<>"Complete")*('Master Schedule'!$AK$6:$AK$500<>"Not Started")*('Master Schedule'!$F$6:$F$500="Urgent")*('Master Schedule'!$A$6:$A$500<>"")) | E15: =SUMPRODUCT(('Master Schedule'!$AK$6:$AK$500<>"Complete")*('Master Schedule'!$AK$6:$AK$500<>"Not Started")*('Master Schedule'!$F$6:$F$500="High")*('Master Schedule'!$A$6:$A$500<>"")) | F15: =SUMPRODUCT(('Master Schedule'!$AK$6:$AK$500<>"Complete")*('Master Schedule'!$AK$6:$AK$500<>"Not Started")*('Master Schedule'!$F$6:$F$500="Normal")*('Master Schedule'!$A$6:$A$500<>"")) | G15: =SUMPRODUCT(('Master Schedule'!$AK$6:$AK$500<>"Complete")*('Master Schedule'!$AK$6:$AK$500<>"Not Started")*('Master Schedule'!$F$6:$F$500="Low")*('Master Schedule'!$A$6:$A$500<>"")) | H15: =SUMPRODUCT(('Master Schedule'!$AK$6:$AK$500<>"Complete")*('Master Schedule'!$AK$6:$AK$500<>"Not Started")*('Master Schedule'!$J$6:$J$500<0)*('Master Schedule'!$A$6:$A$500<>"")) | I15: =SUMPRODUCT(('Master Schedule'!$AK$6:$AK$500<>"Complete")*('Master Schedule'!$AK$6:$AK$500<>"Not Started")*('Master Schedule'!$J$6:$J$500>=0)*('Master Schedule'!$J$6:$J$500<=7)*('Master Schedule'!$A$6:$A$500<>"")) | J15: =IFERROR(SUMPRODUCT(('Master Schedule'!$AK$6:$AK$500="Complete")*('Master Schedule'!$A$6:$A$500<>""))/SUMPRODUCT(('Master Schedule'!$A$6:$A$500<>"")*1),0)
A16: Weld 2 | B16: =SUMPRODUCT(('Master Schedule'!$AO$6:$AO$500<>"Complete")*('Master Schedule'!$AO$6:$AO$500<>"Not Started")*('Master Schedule'!$A$6:$A$500<>"")) | C16: =SUMPRODUCT(('Master Schedule'!$AO$6:$AO$500<>"Complete")*('Master Schedule'!$A$6:$A$500<>"")*'Master Schedule'!$AP$6:$AP$500) | D16: =SUMPRODUCT(('Master Schedule'!$AO$6:$AO$500<>"Complete")*('Master Schedule'!$AO$6:$AO$500<>"Not Started")*('Master Schedule'!$F$6:$F$500="Urgent")*('Master Schedule'!$A$6:$A$500<>"")) | E16: =SUMPRODUCT(('Master Schedule'!$AO$6:$AO$500<>"Complete")*('Master Schedule'!$AO$6:$AO$500<>"Not Started")*('Master Schedule'!$F$6:$F$500="High")*('Master Schedule'!$A$6:$A$500<>"")) | F16: =SUMPRODUCT(('Master Schedule'!$AO$6:$AO$500<>"Complete")*('Master Schedule'!$AO$6:$AO$500<>"Not Started")*('Master Schedule'!$F$6:$F$500="Normal")*('Master Schedule'!$A$6:$A$500<>"")) | G16: =SUMPRODUCT(('Master Schedule'!$AO$6:$AO$500<>"Complete")*('Master Schedule'!$AO$6:$AO$500<>"Not Started")*('Master Schedule'!$F$6:$F$500="Low")*('Master Schedule'!$A$6:$A$500<>"")) | H16: =SUMPRODUCT(('Master Schedule'!$AO$6:$AO$500<>"Complete")*('Master Schedule'!$AO$6:$AO$500<>"Not Started")*('Master Schedule'!$J$6:$J$500<0)*('Master Schedule'!$A$6:$A$500<>"")) | I16: =SUMPRODUCT(('Master Schedule'!$AO$6:$AO$500<>"Complete")*('Master Schedule'!$AO$6:$AO$500<>"Not Started")*('Master Schedule'!$J$6:$J$500>=0)*('Master Schedule'!$J$6:$J$500<=7)*('Master Schedule'!$A$6:$A$500<>"")) | J16: =IFERROR(SUMPRODUCT(('Master Schedule'!$AO$6:$AO$500="Complete")*('Master Schedule'!$A$6:$A$500<>""))/SUMPRODUCT(('Master Schedule'!$A$6:$A$500<>"")*1),0)
A17: Weld 3 | B17: =SUMPRODUCT(('Master Schedule'!$AS$6:$AS$500<>"Complete")*('Master Schedule'!$AS$6:$AS$500<>"Not Started")*('Master Schedule'!$A$6:$A$500<>"")) | C17: =SUMPRODUCT(('Master Schedule'!$AS$6:$AS$500<>"Complete")*('Master Schedule'!$A$6:$A$500<>"")*'Master Schedule'!$AT$6:$AT$500) | D17: =SUMPRODUCT(('Master Schedule'!$AS$6:$AS$500<>"Complete")*('Master Schedule'!$AS$6:$AS$500<>"Not Started")*('Master Schedule'!$F$6:$F$500="Urgent")*('Master Schedule'!$A$6:$A$500<>"")) | E17: =SUMPRODUCT(('Master Schedule'!$AS$6:$AS$500<>"Complete")*('Master Schedule'!$AS$6:$AS$500<>"Not Started")*('Master Schedule'!$F$6:$F$500="High")*('Master Schedule'!$A$6:$A$500<>"")) | F17: =SUMPRODUCT(('Master Schedule'!$AS$6:$AS$500<>"Complete")*('Master Schedule'!$AS$6:$AS$500<>"Not Started")*('Master Schedule'!$F$6:$F$500="Normal")*('Master Schedule'!$A$6:$A$500<>"")) | G17: =SUMPRODUCT(('Master Schedule'!$AS$6:$AS$500<>"Complete")*('Master Schedule'!$AS$6:$AS$500<>"Not Started")*('Master Schedule'!$F$6:$F$500="Low")*('Master Schedule'!$A$6:$A$500<>"")) | H17: =SUMPRODUCT(('Master Schedule'!$AS$6:$AS$500<>"Complete")*('Master Schedule'!$AS$6:$AS$500<>"Not Started")*('Master Schedule'!$J$6:$J$500<0)*('Master Schedule'!$A$6:$A$500<>"")) | I17: =SUMPRODUCT(('Master Schedule'!$AS$6:$AS$500<>"Complete")*('Master Schedule'!$AS$6:$AS$500<>"Not Started")*('Master Schedule'!$J$6:$J$500>=0)*('Master Schedule'!$J$6:$J$500<=7)*('Master Schedule'!$A$6:$A$500<>"")) | J17: =IFERROR(SUMPRODUCT(('Master Schedule'!$AS$6:$AS$500="Complete")*('Master Schedule'!$A$6:$A$500<>""))/SUMPRODUCT(('Master Schedule'!$A$6:$A$500<>"")*1),0)
A18: Blast | B18: =SUMPRODUCT(('Master Schedule'!$AW$6:$AW$500<>"Complete")*('Master Schedule'!$AW$6:$AW$500<>"Not Started")*('Master Schedule'!$A$6:$A$500<>"")) | C18: =SUMPRODUCT(('Master Schedule'!$AW$6:$AW$500<>"Complete")*('Master Schedule'!$A$6:$A$500<>"")*'Master Schedule'!$AX$6:$AX$500) | D18: =SUMPRODUCT(('Master Schedule'!$AW$6:$AW$500<>"Complete")*('Master Schedule'!$AW$6:$AW$500<>"Not Started")*('Master Schedule'!$F$6:$F$500="Urgent")*('Master Schedule'!$A$6:$A$500<>"")) | E18: =SUMPRODUCT(('Master Schedule'!$AW$6:$AW$500<>"Complete")*('Master Schedule'!$AW$6:$AW$500<>"Not Started")*('Master Schedule'!$F$6:$F$500="High")*('Master Schedule'!$A$6:$A$500<>"")) | F18: =SUMPRODUCT(('Master Schedule'!$AW$6:$AW$500<>"Complete")*('Master Schedule'!$AW$6:$AW$500<>"Not Started")*('Master Schedule'!$F$6:$F$500="Normal")*('Master Schedule'!$A$6:$A$500<>"")) | G18: =SUMPRODUCT(('Master Schedule'!$AW$6:$AW$500<>"Complete")*('Master Schedule'!$AW$6:$AW$500<>"Not Started")*('Master Schedule'!$F$6:$F$500="Low")*('Master Schedule'!$A$6:$A$500<>"")) | H18: =SUMPRODUCT(('Master Schedule'!$AW$6:$AW$500<>"Complete")*('Master Schedule'!$AW$6:$AW$500<>"Not Started")*('Master Schedule'!$J$6:$J$500<0)*('Master Schedule'!$A$6:$A$500<>"")) | I18: =SUMPRODUCT(('Master Schedule'!$AW$6:$AW$500<>"Complete")*('Master Schedule'!$AW$6:$AW$500<>"Not Started")*('Master Schedule'!$J$6:$J$500>=0)*('Master Schedule'!$J$6:$J$500<=7)*('Master Schedule'!$A$6:$A$500<>"")) | J18: =IFERROR(SUMPRODUCT(('Master Schedule'!$AW$6:$AW$500="Complete")*('Master Schedule'!$A$6:$A$500<>""))/SUMPRODUCT(('Master Schedule'!$A$6:$A$500<>"")*1),0)
A19: Paint | B19: =SUMPRODUCT(('Master Schedule'!$BA$6:$BA$500<>"Complete")*('Master Schedule'!$BA$6:$BA$500<>"Not Started")*('Master Schedule'!$A$6:$A$500<>"")) | C19: =SUMPRODUCT(('Master Schedule'!$BA$6:$BA$500<>"Complete")*('Master Schedule'!$A$6:$A$500<>"")*'Master Schedule'!$BB$6:$BB$500) | D19: =SUMPRODUCT(('Master Schedule'!$BA$6:$BA$500<>"Complete")*('Master Schedule'!$BA$6:$BA$500<>"Not Started")*('Master Schedule'!$F$6:$F$500="Urgent")*('Master Schedule'!$A$6:$A$500<>"")) | E19: =SUMPRODUCT(('Master Schedule'!$BA$6:$BA$500<>"Complete")*('Master Schedule'!$BA$6:$BA$500<>"Not Started")*('Master Schedule'!$F$6:$F$500="High")*('Master Schedule'!$A$6:$A$500<>"")) | F19: =SUMPRODUCT(('Master Schedule'!$BA$6:$BA$500<>"Complete")*('Master Schedule'!$BA$6:$BA$500<>"Not Started")*('Master Schedule'!$F$6:$F$500="Normal")*('Master Schedule'!$A$6:$A$500<>"")) | G19: =SUMPRODUCT(('Master Schedule'!$BA$6:$BA$500<>"Complete")*('Master Schedule'!$BA$6:$BA$500<>"Not Started")*('Master Schedule'!$F$6:$F$500="Low")*('Master Schedule'!$A$6:$A$500<>"")) | H19: =SUMPRODUCT(('Master Schedule'!$BA$6:$BA$500<>"Complete")*('Master Schedule'!$BA$6:$BA$500<>"Not Started")*('Master Schedule'!$J$6:$J$500<0)*('Master Schedule'!$A$6:$A$500<>"")) | I19: =SUMPRODUCT(('Master Schedule'!$BA$6:$BA$500<>"Complete")*('Master Schedule'!$BA$6:$BA$500<>"Not Started")*('Master Schedule'!$J$6:$J$500>=0)*('Master Schedule'!$J$6:$J$500<=7)*('Master Schedule'!$A$6:$A$500<>"")) | J19: =IFERROR(SUMPRODUCT(('Master Schedule'!$BA$6:$BA$500="Complete")*('Master Schedule'!$A$6:$A$500<>""))/SUMPRODUCT(('Master Schedule'!$A$6:$A$500<>"")*1),0)
A20: Assembly 1 | B20: =SUMPRODUCT(('Master Schedule'!$BE$6:$BE$500<>"Complete")*('Master Schedule'!$BE$6:$BE$500<>"Not Started")*('Master Schedule'!$A$6:$A$500<>"")) | C20: =SUMPRODUCT(('Master Schedule'!$BE$6:$BE$500<>"Complete")*('Master Schedule'!$A$6:$A$500<>"")*'Master Schedule'!$BF$6:$BF$500) | D20: =SUMPRODUCT(('Master Schedule'!$BE$6:$BE$500<>"Complete")*('Master Schedule'!$BE$6:$BE$500<>"Not Started")*('Master Schedule'!$F$6:$F$500="Urgent")*('Master Schedule'!$A$6:$A$500<>"")) | E20: =SUMPRODUCT(('Master Schedule'!$BE$6:$BE$500<>"Complete")*('Master Schedule'!$BE$6:$BE$500<>"Not Started")*('Master Schedule'!$F$6:$F$500="High")*('Master Schedule'!$A$6:$A$500<>"")) | F20: =SUMPRODUCT(('Master Schedule'!$BE$6:$BE$500<>"Complete")*('Master Schedule'!$BE$6:$BE$500<>"Not Started")*('Master Schedule'!$F$6:$F$500="Normal")*('Master Schedule'!$A$6:$A$500<>"")) | G20: =SUMPRODUCT(('Master Schedule'!$BE$6:$BE$500<>"Complete")*('Master Schedule'!$BE$6:$BE$500<>"Not Started")*('Master Schedule'!$F$6:$F$500="Low")*('Master Schedule'!$A$6:$A$500<>"")) | H20: =SUMPRODUCT(('Master Schedule'!$BE$6:$BE$500<>"Complete")*('Master Schedule'!$BE$6:$BE$500<>"Not Started")*('Master Schedule'!$J$6:$J$500<0)*('Master Schedule'!$A$6:$A$500<>"")) | I20: =SUMPRODUCT(('Master Schedule'!$BE$6:$BE$500<>"Complete")*('Master Schedule'!$BE$6:$BE$500<>"Not Started")*('Master Schedule'!$J$6:$J$500>=0)*('Master Schedule'!$J$6:$J$500<=7)*('Master Schedule'!$A$6:$A$500<>"")) | J20: =IFERROR(SUMPRODUCT(('Master Schedule'!$BE$6:$BE$500="Complete")*('Master Schedule'!$A$6:$A$500<>""))/SUMPRODUCT(('Master Schedule'!$A$6:$A$500<>"")*1),0)
A21: Assembly 2 | B21: =SUMPRODUCT(('Master Schedule'!$BI$6:$BI$500<>"Complete")*('Master Schedule'!$BI$6:$BI$500<>"Not Started")*('Master Schedule'!$A$6:$A$500<>"")) | C21: =SUMPRODUCT(('Master Schedule'!$BI$6:$BI$500<>"Complete")*('Master Schedule'!$A$6:$A$500<>"")*'Master Schedule'!$BJ$6:$BJ$500) | D21: =SUMPRODUCT(('Master Schedule'!$BI$6:$BI$500<>"Complete")*('Master Schedule'!$BI$6:$BI$500<>"Not Started")*('Master Schedule'!$F$6:$F$500="Urgent")*('Master Schedule'!$A$6:$A$500<>"")) | E21: =SUMPRODUCT(('Master Schedule'!$BI$6:$BI$500<>"Complete")*('Master Schedule'!$BI$6:$BI$500<>"Not Started")*('Master Schedule'!$F$6:$F$500="High")*('Master Schedule'!$A$6:$A$500<>"")) | F21: =SUMPRODUCT(('Master Schedule'!$BI$6:$BI$500<>"Complete")*('Master Schedule'!$BI$6:$BI$500<>"Not Started")*('Master Schedule'!$F$6:$F$500="Normal")*('Master Schedule'!$A$6:$A$500<>"")) | G21: =SUMPRODUCT(('Master Schedule'!$BI$6:$BI$500<>"Complete")*('Master Schedule'!$BI$6:$BI$500<>"Not Started")*('Master Schedule'!$F$6:$F$500="Low")*('Master Schedule'!$A$6:$A$500<>"")) | H21: =SUMPRODUCT(('Master Schedule'!$BI$6:$BI$500<>"Complete")*('Master Schedule'!$BI$6:$BI$500<>"Not Started")*('Master Schedule'!$J$6:$J$500<0)*('Master Schedule'!$A$6:$A$500<>"")) | I21: =SUMPRODUCT(('Master Schedule'!$BI$6:$BI$500<>"Complete")*('Master Schedule'!$BI$6:$BI$500<>"Not Started")*('Master Schedule'!$J$6:$J$500>=0)*('Master Schedule'!$J$6:$J$500<=7)*('Master Schedule'!$A$6:$A$500<>"")) | J21: =IFERROR(SUMPRODUCT(('Master Schedule'!$BI$6:$BI$500="Complete")*('Master Schedule'!$A$6:$A$500<>""))/SUMPRODUCT(('Master Schedule'!$A$6:$A$500<>"")*1),0)
A22: TOTAL | B22: =SUM(B9:B21) | C22: =SUM(C9:C21) | D22: =SUM(D9:D21) | E22: =SUM(E9:E21) | F22: =SUM(F9:F21) | G22: =SUM(G9:G21) | H22: =SUM(H9:H21) | I22: =SUM(I9:I21)

Sheet Queue — All
A1: QUEUE — ALL STATIONS
A2: Use dropdowns to filter by Work Centre and Priority
A4: Work Centre: | B4: All | C4: Priority: | D4: All
A7: # | B7: Job ID | C7: Customer | D7: Product/Description | E7: Drawing Ref | F7: Job Priority | G7: Overall Status | H7: Order Due Date | I7: Days Until Due | J7: Assigned Station | K7: Notes
A8: =IFERROR(_xlfn._xlws.SEQUENCE(ROWS(_xlfn._xlws.FILTER('Master Schedule'!$A$6:$A$500,('Master Schedule'!$A$6:$A$500<>"")*IF($D$4="All",1,'Master Schedule'!$F$6:$F$500=$D$4)))),"") | B8: =IFERROR(_xlfn._xlws.SORTBY(_xlfn._xlws.FILTER('Master Schedule'!$A$6:$A$500,('Master Schedule'!$A$6:$A$500<>"")*IF($D$4="All",1,'Master Schedule'!$F$6:$F$500=$D$4)),_xlfn._xlws.FILTER('Master Schedule'!$K$6:$K$500,('Master Schedule'!$A$6:$A$500<>"")*IF($D$4="All",1,'Master Schedule'!$F$6:$F$500=$D$4)),1,_xlfn._xlws.FILTER('Master Schedule'!$H$6:$H$500,('Master Schedule'!$A$6:$A$500<>"")*IF($D$4="All",1,'Master Schedule'!$F$6:$F$500=$D$4)),1),"") | C8: =IFERROR(_xlfn._xlws.SORTBY(_xlfn._xlws.FILTER('Master Schedule'!$B$6:$B$500,('Master Schedule'!$A$6:$A$500<>"")*IF($D$4="All",1,'Master Schedule'!$F$6:$F$500=$D$4)),_xlfn._xlws.FILTER('Master Schedule'!$K$6:$K$500,('Master Schedule'!$A$6:$A$500<>"")*IF($D$4="All",1,'Master Schedule'!$F$6:$F$500=$D$4)),1,_xlfn._xlws.FILTER('Master Schedule'!$H$6:$H$500,('Master Schedule'!$A$6:$A$500<>"")*IF($D$4="All",1,'Master Schedule'!$F$6:$F$500=$D$4)),1),"") | D8: =IFERROR(_xlfn._xlws.SORTBY(_xlfn._xlws.FILTER('Master Schedule'!$C$6:$C$500,('Master Schedule'!$A$6:$A$500<>"")*IF($D$4="All",1,'Master Schedule'!$F$6:$F$500=$D$4)),_xlfn._xlws.FILTER('Master Schedule'!$K$6:$K$500,('Master Schedule'!$A$6:$A$500<>"")*IF($D$4="All",1,'Master Schedule'!$F$6:$F$500=$D$4)),1,_xlfn._xlws.FILTER('Master Schedule'!$H$6:$H$500,('Master Schedule'!$A$6:$A$500<>"")*IF($D$4="All",1,'Master Schedule'!$F$6:$F$500=$D$4)),1),"") | E8: =IFERROR(_xlfn._xlws.SORTBY(_xlfn._xlws.FILTER('Master Schedule'!$E$6:$E$500,('Master Schedule'!$A$6:$A$500<>"")*IF($D$4="All",1,'Master Schedule'!$F$6:$F$500=$D$4)),_xlfn._xlws.FILTER('Master Schedule'!$K$6:$K$500,('Master Schedule'!$A$6:$A$500<>"")*IF($D$4="All",1,'Master Schedule'!$F$6:$F$500=$D$4)),1,_xlfn._xlws.FILTER('Master Schedule'!$H$6:$H$500,('Master Schedule'!$A$6:$A$500<>"")*IF($D$4="All",1,'Master Schedule'!$F$6:$F$500=$D$4)),1),"") | F8: =IFERROR(_xlfn._xlws.SORTBY(_xlfn._xlws.FILTER('Master Schedule'!$F$6:$F$500,('Master Schedule'!$A$6:$A$500<>"")*IF($D$4="All",1,'Master Schedule'!$F$6:$F$500=$D$4)),_xlfn._xlws.FILTER('Master Schedule'!$K$6:$K$500,('Master Schedule'!$A$6:$A$500<>"")*IF($D$4="All",1,'Master Schedule'!$F$6:$F$500=$D$4)),1,_xlfn._xlws.FILTER('Master Schedule'!$H$6:$H$500,('Master Schedule'!$A$6:$A$500<>"")*IF($D$4="All",1,'Master Schedule'!$F$6:$F$500=$D$4)),1),"") | G8: =IFERROR(_xlfn._xlws.SORTBY(_xlfn._xlws.FILTER('Master Schedule'!$G$6:$G$500,('Master Schedule'!$A$6:$A$500<>"")*IF($D$4="All",1,'Master Schedule'!$F$6:$F$500=$D$4)),_xlfn._xlws.FILTER('Master Schedule'!$K$6:$K$500,('Master Schedule'!$A$6:$A$500<>"")*IF($D$4="All",1,'Master Schedule'!$F$6:$F$500=$D$4)),1,_xlfn._xlws.FILTER('Master Schedule'!$H$6:$H$500,('Master Schedule'!$A$6:$A$500<>"")*IF($D$4="All",1,'Master Schedule'!$F$6:$F$500=$D$4)),1),"") | H8: =IFERROR(_xlfn._xlws.SORTBY(_xlfn._xlws.FILTER('Master Schedule'!$H$6:$H$500,('Master Schedule'!$A$6:$A$500<>"")*IF($D$4="All",1,'Master Schedule'!$F$6:$F$500=$D$4)),_xlfn._xlws.FILTER('Master Schedule'!$K$6:$K$500,('Master Schedule'!$A$6:$A$500<>"")*IF($D$4="All",1,'Master Schedule'!$F$6:$F$500=$D$4)),1,_xlfn._xlws.FILTER('Master Schedule'!$H$6:$H$500,('Master Schedule'!$A$6:$A$500<>"")*IF($D$4="All",1,'Master Schedule'!$F$6:$F$500=$D$4)),1),"") | I8: =IFERROR(_xlfn._xlws.SORTBY(_xlfn._xlws.FILTER('Master Schedule'!$J$6:$J$500,('Master Schedule'!$A$6:$A$500<>"")*IF($D$4="All",1,'Master Schedule'!$F$6:$F$500=$D$4)),_xlfn._xlws.FILTER('Master Schedule'!$K$6:$K$500,('Master Schedule'!$A$6:$A$500<>"")*IF($D$4="All",1,'Master Schedule'!$F$6:$F$500=$D$4)),1,_xlfn._xlws.FILTER('Master Schedule'!$H$6:$H$500,('Master Schedule'!$A$6:$A$500<>"")*IF($D$4="All",1,'Master Schedule'!$F$6:$F$500=$D$4)),1),"") | J8: =IFERROR(_xlfn._xlws.SORTBY(_xlfn._xlws.FILTER('Master Schedule'!$G$6:$G$500,('Master Schedule'!$A$6:$A$500<>"")*IF($D$4="All",1,'Master Schedule'!$F$6:$F$500=$D$4)),_xlfn._xlws.FILTER('Master Schedule'!$K$6:$K$500,('Master Schedule'!$A$6:$A$500<>"")*IF($D$4="All",1,'Master Schedule'!$F$6:$F$500=$D$4)),1,_xlfn._xlws.FILTER('Master Schedule'!$H$6:$H$500,('Master Schedule'!$A$6:$A$500<>"")*IF($D$4="All",1,'Master Schedule'!$F$6:$F$500=$D$4)),1),"") | K8: =IFERROR(_xlfn._xlws.SORTBY(_xlfn._xlws.FILTER('Master Schedule'!$L$6:$L$500,('Master Schedule'!$A$6:$A$500<>"")*IF($D$4="All",1,'Master Schedule'!$F$6:$F$500=$D$4)),_xlfn._xlws.FILTER('Master Schedule'!$K$6:$K$500,('Master Schedule'!$A$6:$A$500<>"")*IF($D$4="All",1,'Master Schedule'!$F$6:$F$500=$D$4)),1,_xlfn._xlws.FILTER('Master Schedule'!$H$6:$H$500,('Master Schedule'!$A$6:$A$500<>"")*IF($D$4="All",1,'Master Schedule'!$F$6:$F$500=$D$4)),1),"")

Sheet Queue — Profiling
A1: QUEUE — PROFILING
A2: Jobs in Queue | D2: Remaining Hrs | G2: Overdue | J2: Urgent
A3: =SUMPRODUCT(('Master Schedule'!$M$6:$M$500<>"Not Started")*('Master Schedule'!$M$6:$M$500<>"Complete")*('Master Schedule'!$A$6:$A$500<>"")) | D3: =SUMPRODUCT(('Master Schedule'!$M$6:$M$500<>"Complete")*('Master Schedule'!$A$6:$A$500<>"")*'Master Schedule'!$N$6:$N$500) | G3: =SUMPRODUCT(('Master Schedule'!$M$6:$M$500<>"Not Started")*('Master Schedule'!$M$6:$M$500<>"Complete")*('Master Schedule'!$J$6:$J$500<0)*('Master Schedule'!$A$6:$A$500<>"")) | J3: =SUMPRODUCT(('Master Schedule'!$M$6:$M$500<>"Complete")*('Master Schedule'!$F$6:$F$500="Urgent")*('Master Schedule'!$A$6:$A$500<>""))
A7: # | B7: Job ID | C7: Customer | D7: Product/Description | E7: Drawing Ref | F7: Job Priority | G7: Order Due Date | H7: Days Until Due | I7: Profiling Status | J7: Profiling Est Hrs | K7: Profiling Operator | L7: Profiling Notes
A8: =IFERROR(_xlfn._xlws.SEQUENCE(ROWS(_xlfn._xlws.FILTER('Master Schedule'!$A$6:$A$500,('Master Schedule'!$M$6:$M$500<>"Not Started")*('Master Schedule'!$A$6:$A$500<>"")))),"") | B8: =IFERROR(_xlfn._xlws.SORTBY(_xlfn._xlws.FILTER('Master Schedule'!$A$6:$A$500,('Master Schedule'!$M$6:$M$500<>"Not Started")*('Master Schedule'!$A$6:$A$500<>"")),_xlfn._xlws.FILTER('Master Schedule'!$K$6:$K$500,('Master Schedule'!$M$6:$M$500<>"Not Started")*('Master Schedule'!$A$6:$A$500<>"")),1,_xlfn._xlws.FILTER('Master Schedule'!$H$6:$H$500,('Master Schedule'!$M$6:$M$500<>"Not Started")*('Master Schedule'!$A$6:$A$500<>"")),1),"") | C8: =IFERROR(_xlfn._xlws.SORTBY(_xlfn._xlws.FILTER('Master Schedule'!$B$6:$B$500,('Master Schedule'!$M$6:$M$500<>"Not Started")*('Master Schedule'!$A$6:$A$500<>"")),_xlfn._xlws.FILTER('Master Schedule'!$K$6:$K$500,('Master Schedule'!$M$6:$M$500<>"Not Started")*('Master Schedule'!$A$6:$A$500<>"")),1,_xlfn._xlws.FILTER('Master Schedule'!$H$6:$H$500,('Master Schedule'!$M$6:$M$500<>"Not Started")*('Master Schedule'!$A$6:$A$500<>"")),1),"") | D8: =IFERROR(_xlfn._xlws.SORTBY(_xlfn._xlws.FILTER('Master Schedule'!$C$6:$C$500,('Master Schedule'!$M$6:$M$500<>"Not Started")*('Master Schedule'!$A$6:$A$500<>"")),_xlfn._xlws.FILTER('Master Schedule'!$K$6:$K$500,('Master Schedule'!$M$6:$M$500<>"Not Started")*('Master Schedule'!$A$6:$A$500<>"")),1,_xlfn._xlws.FILTER('Master Schedule'!$H$6:$H$500,('Master Schedule'!$M$6:$M$500<>"Not Started")*('Master Schedule'!$A$6:$A$500<>"")),1),"") | E8: =IFERROR(_xlfn._xlws.SORTBY(_xlfn._xlws.FILTER('Master Schedule'!$E$6:$E$500,('Master Schedule'!$M$6:$M$500<>"Not Started")*('Master Schedule'!$A$6:$A$500<>"")),_xlfn._xlws.FILTER('Master Schedule'!$K$6:$K$500,('Master Schedule'!$M$6:$M$500<>"Not Started")*('Master Schedule'!$A$6:$A$500<>"")),1,_xlfn._xlws.FILTER('Master Schedule'!$H$6:$H$500,('Master Schedule'!$M$6:$M$500<>"Not Started")*('Master Schedule'!$A$6:$A$500<>"")),1),"") | F8: =IFERROR(_xlfn._xlws.SORTBY(_xlfn._xlws.FILTER('Master Schedule'!$F$6:$F$500,('Master Schedule'!$M$6:$M$500<>"Not Started")*('Master Schedule'!$A$6:$A$500<>"")),_xlfn._xlws.FILTER('Master Schedule'!$K$6:$K$500,('Master Schedule'!$M$6:$M$500<>"Not Started")*('Master Schedule'!$A$6:$A$500<>"")),1,_xlfn._xlws.FILTER('Master Schedule'!$H$6:$H$500,('Master Schedule'!$M$6:$M$500<>"Not Started")*('Master Schedule'!$A$6:$A$500<>"")),1),"") | G8: =IFERROR(_xlfn._xlws.SORTBY(_xlfn._xlws.FILTER('Master Schedule'!$H$6:$H$500,('Master Schedule'!$M$6:$M$500<>"Not Started")*('Master Schedule'!$A$6:$A$500<>"")),_xlfn._xlws.FILTER('Master Schedule'!$K$6:$K$500,('Master Schedule'!$M$6:$M$500<>"Not Started")*('Master Schedule'!$A$6:$A$500<>"")),1,_xlfn._xlws.FILTER('Master Schedule'!$H$6:$H$500,('Master Schedule'!$M$6:$M$500<>"Not Started")*('Master Schedule'!$A$6:$A$500<>"")),1),"") | H8: =IFERROR(_xlfn._xlws.SORTBY(_xlfn._xlws.FILTER('Master Schedule'!$J$6:$J$500,('Master Schedule'!$M$6:$M$500<>"Not Started")*('Master Schedule'!$A$6:$A$500<>"")),_xlfn._xlws.FILTER('Master Schedule'!$K$6:$K$500,('Master Schedule'!$M$6:$M$500<>"Not Started")*('Master Schedule'!$A$6:$A$500<>"")),1,_xlfn._xlws.FILTER('Master Schedule'!$H$6:$H$500,('Master Schedule'!$M$6:$M$500<>"Not Started")*('Master Schedule'!$A$6:$A$500<>"")),1),"") | I8: =IFERROR(_xlfn._xlws.SORTBY(_xlfn._xlws.FILTER('Master Schedule'!$M$6:$M$500,('Master Schedule'!$M$6:$M$500<>"Not Started")*('Master Schedule'!$A$6:$A$500<>"")),_xlfn._xlws.FILTER('Master Schedule'!$K$6:$K$500,('Master Schedule'!$M$6:$M$500<>"Not Started")*('Master Schedule'!$A$6:$A$500<>"")),1,_xlfn._xlws.FILTER('Master Schedule'!$H$6:$H$500,('Master Schedule'!$M$6:$M$500<>"Not Started")*('Master Schedule'!$A$6:$A$500<>"")),1),"") | J8: =IFERROR(_xlfn._xlws.SORTBY(_xlfn._xlws.FILTER('Master Schedule'!$N$6:$N$500,('Master Schedule'!$M$6:$M$500<>"Not Started")*('Master Schedule'!$A$6:$A$500<>"")),_xlfn._xlws.FILTER('Master Schedule'!$K$6:$K$500,('Master Schedule'!$M$6:$M$500<>"Not Started")*('Master Schedule'!$A$6:$A$500<>"")),1,_xlfn._xlws.FILTER('Master Schedule'!$H$6:$H$500,('Master Schedule'!$M$6:$M$500<>"Not Started")*('Master Schedule'!$A$6:$A$500<>"")),1),"") | K8: =IFERROR(_xlfn._xlws.SORTBY(_xlfn._xlws.FILTER('Master Schedule'!$O$6:$O$500,('Master Schedule'!$M$6:$M$500<>"Not Started")*('Master Schedule'!$A$6:$A$500<>"")),_xlfn._xlws.FILTER('Master Schedule'!$K$6:$K$500,('Master Schedule'!$M$6:$M$500<>"Not Started")*('Master Schedule'!$A$6:$A$500<>"")),1,_xlfn._xlws.FILTER('Master Schedule'!$H$6:$H$500,('Master Schedule'!$M$6:$M$500<>"Not Started")*('Master Schedule'!$A$6:$A$500<>"")),1),"") | L8: =IFERROR(_xlfn._xlws.SORTBY(_xlfn._xlws.FILTER('Master Schedule'!$P$6:$P$500,('Master Schedule'!$M$6:$M$500<>"Not Started")*('Master Schedule'!$A$6:$A$500<>"")),_xlfn._xlws.FILTER('Master Schedule'!$K$6:$K$500,('Master Schedule'!$M$6:$M$500<>"Not Started")*('Master Schedule'!$A$6:$A$500<>"")),1,_xlfn._xlws.FILTER('Master Schedule'!$H$6:$H$500,('Master Schedule'!$M$6:$M$500<>"Not Started")*('Master Schedule'!$A$6:$A$500<>"")),1),"")

Sheet Queue — Saw
A1: QUEUE — SAW
A2: Jobs in Queue | D2: Remaining Hrs | G2: Overdue | J2: Urgent
A3: =SUMPRODUCT(('Master Schedule'!$Q$6:$Q$500<>"Not Started")*('Master Schedule'!$Q$6:$Q$500<>"Complete")*('Master Schedule'!$A$6:$A$500<>"")) | D3: =SUMPRODUCT(('Master Schedule'!$Q$6:$Q$500<>"Complete")*('Master Schedule'!$A$6:$A$500<>"")*'Master Schedule'!$R$6:$R$500) | G3: =SUMPRODUCT(('Master Schedule'!$Q$6:$Q$500<>"Not Started")*('Master Schedule'!$Q$6:$Q$500<>"Complete")*('Master Schedule'!$J$6:$J$500<0)*('Master Schedule'!$A$6:$A$500<>"")) | J3: =SUMPRODUCT(('Master Schedule'!$Q$6:$Q$500<>"Complete")*('Master Schedule'!$F$6:$F$500="Urgent")*('Master Schedule'!$A$6:$A$500<>""))
A7: # | B7: Job ID | C7: Customer | D7: Product/Description | E7: Drawing Ref | F7: Job Priority | G7: Order Due Date | H7: Days Until Due | I7: Saw Status | J7: Saw Est Hrs | K7: Saw Operator | L7: Saw Notes
A8: =IFERROR(_xlfn._xlws.SEQUENCE(ROWS(_xlfn._xlws.FILTER('Master Schedule'!$A$6:$A$500,('Master Schedule'!$Q$6:$Q$500<>"Not Started")*('Master Schedule'!$A$6:$A$500<>"")))),"") | B8: =IFERROR(_xlfn._xlws.SORTBY(_xlfn._xlws.FILTER('Master Schedule'!$A$6:$A$500,('Master Schedule'!$Q$6:$Q$500<>"Not Started")*('Master Schedule'!$A$6:$A$500<>"")),_xlfn._xlws.FILTER('Master Schedule'!$K$6:$K$500,('Master Schedule'!$Q$6:$Q$500<>"Not Started")*('Master Schedule'!$A$6:$A$500<>"")),1,_xlfn._xlws.FILTER('Master Schedule'!$H$6:$H$500,('Master Schedule'!$Q$6:$Q$500<>"Not Started")*('Master Schedule'!$A$6:$A$500<>"")),1),"") | C8: =IFERROR(_xlfn._xlws.SORTBY(_xlfn._xlws.FILTER('Master Schedule'!$B$6:$B$500,('Master Schedule'!$Q$6:$Q$500<>"Not Started")*('Master Schedule'!$A$6:$A$500<>"")),_xlfn._xlws.FILTER('Master Schedule'!$K$6:$K$500,('Master Schedule'!$Q$6:$Q$500<>"Not Started")*('Master Schedule'!$A$6:$A$500<>"")),1,_xlfn._xlws.FILTER('Master Schedule'!$H$6:$H$500,('Master Schedule'!$Q$6:$Q$500<>"Not Started")*('Master Schedule'!$A$6:$A$500<>"")),1),"") | D8: =IFERROR(_xlfn._xlws.SORTBY(_xlfn._xlws.FILTER('Master Schedule'!$C$6:$C$500,('Master Schedule'!$Q$6:$Q$500<>"Not Started")*('Master Schedule'!$A$6:$A$500<>"")),_xlfn._xlws.FILTER('Master Schedule'!$K$6:$K$500,('Master Schedule'!$Q$6:$Q$500<>"Not Started")*('Master Schedule'!$A$6:$A$500<>"")),1,_xlfn._xlws.FILTER('Master Schedule'!$H$6:$H$500,('Master Schedule'!$Q$6:$Q$500<>"Not Started")*('Master Schedule'!$A$6:$A$500<>"")),1),"") | E8: =IFERROR(_xlfn._xlws.SORTBY(_xlfn._xlws.FILTER('Master Schedule'!$E$6:$E$500,('Master Schedule'!$Q$6:$Q$500<>"Not Started")*('Master Schedule'!$A$6:$A$500<>"")),_xlfn._xlws.FILTER('Master Schedule'!$K$6:$K$500,('Master Schedule'!$Q$6:$Q$500<>"Not Started")*('Master Schedule'!$A$6:$A$500<>"")),1,_xlfn._xlws.FILTER('Master Schedule'!$H$6:$H$500,('Master Schedule'!$Q$6:$Q$500<>"Not Started")*('Master Schedule'!$A$6:$A$500<>"")),1),"") | F8: =IFERROR(_xlfn._xlws.SORTBY(_xlfn._xlws.FILTER('Master Schedule'!$F$6:$F$500,('Master Schedule'!$Q$6:$Q$500<>"Not Started")*('Master Schedule'!$A$6:$A$500<>"")),_xlfn._xlws.FILTER('Master Schedule'!$K$6:$K$500,('Master Schedule'!$Q$6:$Q$500<>"Not Started")*('Master Schedule'!$A$6:$A$500<>"")),1,_xlfn._xlws.FILTER('Master Schedule'!$H$6:$H$500,('Master Schedule'!$Q$6:$Q$500<>"Not Started")*('Master Schedule'!$A$6:$A$500<>"")),1),"") | G8: =IFERROR(_xlfn._xlws.SORTBY(_xlfn._xlws.FILTER('Master Schedule'!$H$6:$H$500,('Master Schedule'!$Q$6:$Q$500<>"Not Started")*('Master Schedule'!$A$6:$A$500<>"")),_xlfn._xlws.FILTER('Master Schedule'!$K$6:$K$500,('Master Schedule'!$Q$6:$Q$500<>"Not Started")*('Master Schedule'!$A$6:$A$500<>"")),1,_xlfn._xlws.FILTER('Master Schedule'!$H$6:$H$500,('Master Schedule'!$Q$6:$Q$500<>"Not Started")*('Master Schedule'!$A$6:$A$500<>"")),1),"") | H8: =IFERROR(_xlfn._xlws.SORTBY(_xlfn._xlws.FILTER('Master Schedule'!$J$6:$J$500,('Master Schedule'!$Q$6:$Q$500<>"Not Started")*('Master Schedule'!$A$6:$A$500<>"")),_xlfn._xlws.FILTER('Master Schedule'!$K$6:$K$500,('Master Schedule'!$Q$6:$Q$500<>"Not Started")*('Master Schedule'!$A$6:$A$500<>"")),1,_xlfn._xlws.FILTER('Master Schedule'!$H$6:$H$500,('Master Schedule'!$Q$6:$Q$500<>"Not Started")*('Master Schedule'!$A$6:$A$500<>"")),1),"") | I8: =IFERROR(_xlfn._xlws.SORTBY(_xlfn._xlws.FILTER('Master Schedule'!$Q$6:$Q$500,('Master Schedule'!$Q$6:$Q$500<>"Not Started")*('Master Schedule'!$A$6:$A$500<>"")),_xlfn._xlws.FILTER('Master Schedule'!$K$6:$K$500,('Master Schedule'!$Q$6:$Q$500<>"Not Started")*('Master Schedule'!$A$6:$A$500<>"")),1,_xlfn._xlws.FILTER('Master Schedule'!$H$6:$H$500,('Master Schedule'!$Q$6:$Q$500<>"Not Started")*('Master Schedule'!$A$6:$A$500<>"")),1),"") | J8: =IFERROR(_xlfn._xlws.SORTBY(_xlfn._xlws.FILTER('Master Schedule'!$R$6:$R$500,('Master Schedule'!$Q$6:$Q$500<>"Not Started")*('Master Schedule'!$A$6:$A$500<>"")),_xlfn._xlws.FILTER('Master Schedule'!$K$6:$K$500,('Master Schedule'!$Q$6:$Q$500<>"Not Started")*('Master Schedule'!$A$6:$A$500<>"")),1,_xlfn._xlws.FILTER('Master Schedule'!$H$6:$H$500,('Master Schedule'!$Q$6:$Q$500<>"Not Started")*('Master Schedule'!$A$6:$A$500<>"")),1),"") | K8: =IFERROR(_xlfn._xlws.SORTBY(_xlfn._xlws.FILTER('Master Schedule'!$S$6:$S$500,('Master Schedule'!$Q$6:$Q$500<>"Not Started")*('Master Schedule'!$A$6:$A$500<>"")),_xlfn._xlws.FILTER('Master Schedule'!$K$6:$K$500,('Master Schedule'!$Q$6:$Q$500<>"Not Started")*('Master Schedule'!$A$6:$A$500<>"")),1,_xlfn._xlws.FILTER('Master Schedule'!$H$6:$H$500,('Master Schedule'!$Q$6:$Q$500<>"Not Started")*('Master Schedule'!$A$6:$A$500<>"")),1),"") | L8: =IFERROR(_xlfn._xlws.SORTBY(_xlfn._xlws.FILTER('Master Schedule'!$T$6:$T$500,('Master Schedule'!$Q$6:$Q$500<>"Not Started")*('Master Schedule'!$A$6:$A$500<>"")),_xlfn._xlws.FILTER('Master Schedule'!$K$6:$K$500,('Master Schedule'!$Q$6:$Q$500<>"Not Started")*('Master Schedule'!$A$6:$A$500<>"")),1,_xlfn._xlws.FILTER('Master Schedule'!$H$6:$H$500,('Master Schedule'!$Q$6:$Q$500<>"Not Started")*('Master Schedule'!$A$6:$A$500<>"")),1),"")

Sheet Queue — Machining 1
A1: QUEUE — MACHINING 1
A2: Jobs in Queue | D2: Remaining Hrs | G2: Overdue | J2: Urgent
A3: =SUMPRODUCT(('Master Schedule'!$U$6:$U$500<>"Not Started")*('Master Schedule'!$U$6:$U$500<>"Complete")*('Master Schedule'!$A$6:$A$500<>"")) | D3: =SUMPRODUCT(('Master Schedule'!$U$6:$U$500<>"Complete")*('Master Schedule'!$A$6:$A$500<>"")*'Master Schedule'!$V$6:$V$500) | G3: =SUMPRODUCT(('Master Schedule'!$U$6:$U$500<>"Not Started")*('Master Schedule'!$U$6:$U$500<>"Complete")*('Master Schedule'!$J$6:$J$500<0)*('Master Schedule'!$A$6:$A$500<>"")) | J3: =SUMPRODUCT(('Master Schedule'!$U$6:$U$500<>"Complete")*('Master Schedule'!$F$6:$F$500="Urgent")*('Master Schedule'!$A$6:$A$500<>""))
A7: # | B7: Job ID | C7: Customer | D7: Product/Description | E7: Drawing Ref | F7: Job Priority | G7: Order Due Date | H7: Days Until Due | I7: Machining 1 Status | J7: Machining 1 Est Hrs | K7: Machining 1 Operator | L7: Machining 1 Notes
